Failure # 1 (occurred at 2020-06-01_12-50-08)
Traceback (most recent call last):
  File "/home/nova/anaconda3/envs/lz/lib/python3.6/site-packages/ray/tune/trial_runner.py", line 467, in _process_trial
    result = self.trial_executor.fetch_result(trial)
  File "/home/nova/anaconda3/envs/lz/lib/python3.6/site-packages/ray/tune/ray_trial_executor.py", line 381, in fetch_result
    result = ray.get(trial_future[0], DEFAULT_GET_TIMEOUT)
  File "/home/nova/anaconda3/envs/lz/lib/python3.6/site-packages/ray/worker.py", line 1491, in get
    raise value.as_instanceof_cause()
ray.exceptions.RayTaskError(AtomValenceException): [36mray::PPO.train()[39m (pid=36772, ip=10.0.0.131)
  File "python/ray/_raylet.pyx", line 450, in ray._raylet.execute_task
  File "python/ray/_raylet.pyx", line 405, in ray._raylet.execute_task.function_executor
  File "/home/nova/anaconda3/envs/lz/lib/python3.6/site-packages/ray/rllib/agents/trainer.py", line 502, in train
    raise e
  File "/home/nova/anaconda3/envs/lz/lib/python3.6/site-packages/ray/rllib/agents/trainer.py", line 491, in train
    result = Trainable.train(self)
  File "/home/nova/anaconda3/envs/lz/lib/python3.6/site-packages/ray/tune/trainable.py", line 261, in train
    result = self._train()
  File "/home/nova/anaconda3/envs/lz/lib/python3.6/site-packages/ray/rllib/agents/trainer_template.py", line 150, in _train
    fetches = self.optimizer.step()
  File "/home/nova/anaconda3/envs/lz/lib/python3.6/site-packages/ray/rllib/optimizers/multi_gpu_optimizer.py", line 148, in step
    self.train_batch_size)
  File "/home/nova/anaconda3/envs/lz/lib/python3.6/site-packages/ray/rllib/optimizers/rollout.py", line 25, in collect_samples
    next_sample = ray_get_and_free(fut_sample)
  File "/home/nova/anaconda3/envs/lz/lib/python3.6/site-packages/ray/rllib/utils/memory.py", line 29, in ray_get_and_free
    result = ray.get(object_ids)
ray.exceptions.RayTaskError(AtomValenceException): [36mray::RolloutWorker.sample()[39m (pid=36769, ip=10.0.0.131)
  File "python/ray/_raylet.pyx", line 450, in ray._raylet.execute_task
  File "python/ray/_raylet.pyx", line 405, in ray._raylet.execute_task.function_executor
  File "/home/nova/anaconda3/envs/lz/lib/python3.6/site-packages/ray/rllib/evaluation/rollout_worker.py", line 492, in sample
    batches = [self.input_reader.next()]
  File "/home/nova/anaconda3/envs/lz/lib/python3.6/site-packages/ray/rllib/evaluation/sampler.py", line 53, in next
    batches = [self.get_data()]
  File "/home/nova/anaconda3/envs/lz/lib/python3.6/site-packages/ray/rllib/evaluation/sampler.py", line 96, in get_data
    item = next(self.rollout_provider)
  File "/home/nova/anaconda3/envs/lz/lib/python3.6/site-packages/ray/rllib/evaluation/sampler.py", line 367, in _env_runner
    base_env.send_actions(actions_to_send)
  File "/home/nova/anaconda3/envs/lz/lib/python3.6/site-packages/ray/rllib/env/base_env.py", line 328, in send_actions
    self.vector_env.vector_step(action_vector)
  File "/home/nova/anaconda3/envs/lz/lib/python3.6/site-packages/ray/rllib/env/vector_env.py", line 106, in vector_step
    obs, r, done, info = self.envs[i].step(actions[i])
  File "/home/nova/LambdaZero/LambdaZero/environments/block_mol_v3.py", line 147, in step
    obs = self._make_obs()
  File "/home/nova/LambdaZero/LambdaZero/environments/block_mol_v3.py", line 78, in _make_obs
    mol_fp, stem_fps_, jbond_fps_ = self.get_fps(self.molMDP.molecule)
  File "/home/nova/LambdaZero/LambdaZero/chem/chem_op.py", line 461, in __call__
    mol = molecule.mol
  File "/home/nova/LambdaZero/LambdaZero/environments/molMDP.py", line 138, in mol
    self._mol, _ = chem.mol_from_frag(jun_bonds=self.jbonds, frags=self.blocks)
  File "/home/nova/LambdaZero/LambdaZero/chem/chem_op.py", line 174, in mol_from_frag
    Chem.SanitizeMol(mol)
rdkit.Chem.rdchem.AtomValenceException: Explicit valence for atom # 12 N, 4, is greater than permitted

