Failure # 1 (occurred at 2020-06-01_01-48-48)
Traceback (most recent call last):
  File "/home/nova/anaconda3/envs/lz/lib/python3.6/site-packages/ray/tune/trial_runner.py", line 467, in _process_trial
    result = self.trial_executor.fetch_result(trial)
  File "/home/nova/anaconda3/envs/lz/lib/python3.6/site-packages/ray/tune/ray_trial_executor.py", line 381, in fetch_result
    result = ray.get(trial_future[0], DEFAULT_GET_TIMEOUT)
  File "/home/nova/anaconda3/envs/lz/lib/python3.6/site-packages/ray/worker.py", line 1491, in get
    raise value.as_instanceof_cause()
ray.exceptions.RayTaskError(ValueError): [36mray::PPO.__init__()[39m (pid=18521, ip=10.0.0.131)
  File "python/ray/_raylet.pyx", line 412, in ray._raylet.execute_task
  File "python/ray/_raylet.pyx", line 447, in ray._raylet.execute_task
  File "python/ray/_raylet.pyx", line 448, in ray._raylet.execute_task
  File "python/ray/_raylet.pyx", line 450, in ray._raylet.execute_task
  File "python/ray/_raylet.pyx", line 405, in ray._raylet.execute_task.function_executor
  File "/home/nova/anaconda3/envs/lz/lib/python3.6/site-packages/ray/rllib/agents/trainer_template.py", line 90, in __init__
    Trainer.__init__(self, config, env, logger_creator)
  File "/home/nova/anaconda3/envs/lz/lib/python3.6/site-packages/ray/rllib/agents/trainer.py", line 455, in __init__
    super().__init__(config, logger_creator)
  File "/home/nova/anaconda3/envs/lz/lib/python3.6/site-packages/ray/tune/trainable.py", line 174, in __init__
    self._setup(copy.deepcopy(self.config))
  File "/home/nova/anaconda3/envs/lz/lib/python3.6/site-packages/ray/rllib/agents/trainer.py", line 596, in _setup
    self._init(self.config, self.env_creator)
  File "/home/nova/anaconda3/envs/lz/lib/python3.6/site-packages/ray/rllib/agents/trainer_template.py", line 117, in _init
    self.config["num_workers"])
  File "/home/nova/anaconda3/envs/lz/lib/python3.6/site-packages/ray/rllib/agents/trainer.py", line 667, in _make_workers
    logdir=self.logdir)
  File "/home/nova/anaconda3/envs/lz/lib/python3.6/site-packages/ray/rllib/evaluation/worker_set.py", line 62, in __init__
    RolloutWorker, env_creator, policy, 0, self._local_config)
  File "/home/nova/anaconda3/envs/lz/lib/python3.6/site-packages/ray/rllib/evaluation/worker_set.py", line 272, in _make_worker
    _fake_sampler=config.get("_fake_sampler", False))
  File "/home/nova/anaconda3/envs/lz/lib/python3.6/site-packages/ray/rllib/evaluation/rollout_worker.py", line 287, in __init__
    self.env = _validate_env(env_creator(env_context))
  File "/home/nova/anaconda3/envs/lz/lib/python3.6/site-packages/ray/rllib/agents/trainer.py", line 1074, in <lambda>
    register_env(name, lambda config: env_object(config))
  File "/home/nova/LambdaZero/LambdaZero/environments/block_mol_v3.py", line 73, in __init__
    self.molMDP = MolMDP(**config["molMDP_config"])
  File "/home/nova/LambdaZero/LambdaZero/environments/molMDP.py", line 144, in __init__
    blocks = pd.read_json(blocks_file)
  File "/home/nova/anaconda3/envs/lz/lib/python3.6/site-packages/pandas/util/_decorators.py", line 214, in wrapper
    return func(*args, **kwargs)
  File "/home/nova/anaconda3/envs/lz/lib/python3.6/site-packages/pandas/io/json/_json.py", line 608, in read_json
    result = json_reader.read()
  File "/home/nova/anaconda3/envs/lz/lib/python3.6/site-packages/pandas/io/json/_json.py", line 731, in read
    obj = self._get_object_parser(self.data)
  File "/home/nova/anaconda3/envs/lz/lib/python3.6/site-packages/pandas/io/json/_json.py", line 753, in _get_object_parser
    obj = FrameParser(json, **kwargs).parse()
  File "/home/nova/anaconda3/envs/lz/lib/python3.6/site-packages/pandas/io/json/_json.py", line 857, in parse
    self._parse_no_numpy()
  File "/home/nova/anaconda3/envs/lz/lib/python3.6/site-packages/pandas/io/json/_json.py", line 1089, in _parse_no_numpy
    loads(json, precise_float=self.precise_float), dtype=None
ValueError: Expected object or value

